2024-03-26T17:49:03 {"cpu": 0.04833984375, "cpu_total": 16, "cpu_usage": 0.003021240234375, "memory": 1718.0, "memory_total": 9698.0, "memory_usage": 0.1771499278201691, "pipeline_run_id": 27, "pipeline_schedule_id": 4, "pipeline_uuid": "fore_to_postgres", "hostname": "0db69d3fbb20", "level": "INFO", "message": "Pipeline fore_to_postgres for run 27 in schedule 4 is alive.", "timestamp": 1711475343.592707, "uuid": "8da669207e0b4fc48eaef76fb5e52325"}
2024-03-26T17:49:04 {"cpu": 0.04833984375, "cpu_total": 16, "cpu_usage": 0.003021240234375, "memory": 1781.0, "memory_total": 9698.0, "memory_usage": 0.1836461126005362, "pipeline_run_id": 27, "pipeline_schedule_id": 4, "pipeline_uuid": "fore_to_postgres", "hostname": "0db69d3fbb20", "level": "INFO", "message": "Pipeline fore_to_postgres for run 27 in schedule 4 is alive.", "timestamp": 1711475344.119062, "uuid": "d28d1576af97496c962653c7246f5012"}
2024-03-26T17:49:04 {"block_run_id": 79, "block_uuid": "scrape_full_fore", "pipeline_run_id": 27, "pipeline_schedule_id": 4, "pipeline_uuid": "fore_to_postgres", "hostname": "0db69d3fbb20", "level": "INFO", "message": "Execute PipelineRun 27, BlockRun 79: pipeline fore_to_postgres block scrape_full_fore", "timestamp": 1711475344.275445, "uuid": "9979f113ae4642eba7e2d942e070c6d6"}
2024-03-26T17:49:12 {"cpu": 0.05908203125, "cpu_total": 16, "cpu_usage": 0.003692626953125, "memory": 1994.0, "memory_total": 9698.0, "memory_usage": 0.20560940400082492, "pipeline_run_id": 27, "pipeline_schedule_id": 4, "pipeline_uuid": "fore_to_postgres", "hostname": "0db69d3fbb20", "level": "INFO", "message": "Pipeline fore_to_postgres for run 27 in schedule 4 is alive.", "timestamp": 1711475352.440497, "uuid": "512e9578842c426e83ec28daac076ecc"}
2024-03-26T17:49:22 {"cpu": 0.05810546875, "cpu_total": 16, "cpu_usage": 0.003631591796875, "memory": 2000.0, "memory_total": 9698.0, "memory_usage": 0.20622808826562178, "pipeline_run_id": 27, "pipeline_schedule_id": 4, "pipeline_uuid": "fore_to_postgres", "hostname": "0db69d3fbb20", "level": "INFO", "message": "Pipeline fore_to_postgres for run 27 in schedule 4 is alive.", "timestamp": 1711475362.718007, "uuid": "1b34e33fdd334308bfe2e2a49ae73c12"}
2024-03-26T17:49:26 {"block_run_id": 79, "block_uuid": "scrape_full_fore", "pipeline_run_id": 27, "pipeline_schedule_id": 4, "pipeline_uuid": "fore_to_postgres", "hostname": "0db69d3fbb20", "level": "INFO", "message": "BlockRun 79 (block_uuid: scrape_full_fore) completes.", "timestamp": 1711475366.406019, "uuid": "59557177157c4de89d4fc33005a6ffe2"}
2024-03-26T17:49:32 {"cpu": 0.05712890625, "cpu_total": 16, "cpu_usage": 0.003570556640625, "memory": 1952.0, "memory_total": 9698.0, "memory_usage": 0.20127861414724685, "pipeline_run_id": 27, "pipeline_schedule_id": 4, "pipeline_uuid": "fore_to_postgres", "hostname": "0db69d3fbb20", "level": "INFO", "message": "Pipeline fore_to_postgres for run 27 in schedule 4 is alive.", "timestamp": 1711475372.983648, "uuid": "2f40e7df74294fcb965706bf568356df"}
2024-03-26T17:49:33 {"block_run_id": 80, "block_uuid": "trivial_transform", "pipeline_run_id": 27, "pipeline_schedule_id": 4, "pipeline_uuid": "fore_to_postgres", "hostname": "0db69d3fbb20", "level": "INFO", "message": "Execute PipelineRun 27, BlockRun 80: pipeline fore_to_postgres block trivial_transform", "timestamp": 1711475373.24152, "uuid": "c77420b9fe9c410bb4a1621325b391e0"}
2024-03-26T17:49:33 {"block_run_id": 80, "block_uuid": "trivial_transform", "pipeline_run_id": 27, "pipeline_schedule_id": 4, "pipeline_uuid": "fore_to_postgres", "hostname": "0db69d3fbb20", "level": "INFO", "message": "BlockRun 80 (block_uuid: trivial_transform) completes.", "timestamp": 1711475373.672063, "uuid": "213aa46344c6489e8e596fd478abbabe"}
2024-03-26T17:49:42 {"cpu": 0.05615234375, "cpu_total": 16, "cpu_usage": 0.003509521484375, "memory": 1948.0, "memory_total": 9698.0, "memory_usage": 0.2008661579707156, "pipeline_run_id": 27, "pipeline_schedule_id": 4, "pipeline_uuid": "fore_to_postgres", "hostname": "0db69d3fbb20", "level": "INFO", "message": "Pipeline fore_to_postgres for run 27 in schedule 4 is alive.", "timestamp": 1711475382.337586, "uuid": "47d14b58c8044dd0801c39a4be6723fe"}
2024-03-26T17:49:42 {"block_run_id": 81, "block_uuid": "fore_to_postgres", "pipeline_run_id": 27, "pipeline_schedule_id": 4, "pipeline_uuid": "fore_to_postgres", "hostname": "0db69d3fbb20", "level": "INFO", "message": "Execute PipelineRun 27, BlockRun 81: pipeline fore_to_postgres block fore_to_postgres", "timestamp": 1711475382.574759, "uuid": "6ce04cabf2ce4513a26e058ccf109ca8"}
2024-03-26T17:49:50 {"block_run_id": 81, "block_uuid": "fore_to_postgres", "pipeline_run_id": 27, "pipeline_schedule_id": 4, "pipeline_uuid": "fore_to_postgres", "hostname": "0db69d3fbb20", "level": "EXCEPTION", "message": "BlockRun 81 (block_uuid: fore_to_postgres) failed.", "timestamp": 1711475390.91714, "uuid": "9e5bce35ab444cbabe14d4a1523069aa", "error": ["Traceback (most recent call last):\n  File \"/usr/local/lib/python3.10/site-packages/mage_ai/io/base.py\", line 345, in conn\n    return self._ctx\nAttributeError: 'Postgres' object has no attribute '_ctx'\n\nDuring handling of the above exception, another exception occurred:\n\nTraceback (most recent call last):\n  File \"/usr/local/lib/python3.10/site-packages/mage_ai/data_preparation/executors/block_executor.py\", line 605, in execute\n    result = __execute_with_retry()\n  File \"/usr/local/lib/python3.10/site-packages/mage_ai/shared/retry.py\", line 54, in retry_func\n    raise e\n  File \"/usr/local/lib/python3.10/site-packages/mage_ai/shared/retry.py\", line 38, in retry_func\n    return func(*args, **kwargs)\n  File \"/usr/local/lib/python3.10/site-packages/mage_ai/data_preparation/executors/block_executor.py\", line 578, in __execute_with_retry\n    return self._execute(\n  File \"/usr/local/lib/python3.10/site-packages/mage_ai/data_preparation/executors/block_executor.py\", line 1052, in _execute\n    result = self.block.execute_sync(\n  File \"/usr/local/lib/python3.10/site-packages/mage_ai/data_preparation/models/block/__init__.py\", line 1285, in execute_sync\n    raise err\n  File \"/usr/local/lib/python3.10/site-packages/mage_ai/data_preparation/models/block/__init__.py\", line 1194, in execute_sync\n    output = self.execute_block(\n  File \"/usr/local/lib/python3.10/site-packages/mage_ai/data_preparation/models/block/__init__.py\", line 1509, in execute_block\n    outputs = self._execute_block(\n  File \"/usr/local/lib/python3.10/site-packages/mage_ai/data_preparation/models/block/__init__.py\", line 1665, in _execute_block\n    outputs = self.execute_block_function(\n  File \"/usr/local/lib/python3.10/site-packages/mage_ai/data_preparation/models/block/__init__.py\", line 1704, in execute_block_function\n    output = block_function_updated(*input_vars, **global_vars)\n  File \"<string>\", line 25, in export_data_to_postgres\n  File \"/usr/local/lib/python3.10/site-packages/mage_ai/io/sql.py\", line 359, in export\n    __process()\n  File \"/usr/local/lib/python3.10/site-packages/mage_ai/io/sql.py\", line 292, in __process\n    table_exists = self.table_exists(schema_name, table_name)\n  File \"/usr/local/lib/python3.10/site-packages/mage_ai/io/postgres.py\", line 166, in table_exists\n    with self.conn.cursor() as cur:\n  File \"/usr/local/lib/python3.10/site-packages/mage_ai/io/base.py\", line 347, in conn\n    raise ConnectionError(\nConnectionError: No connection currently open. Open a new connection to access this property.\n"], "error_stack": [["  File \"/usr/local/bin/mage\", line 8, in <module>\n    sys.exit(app())\n", "  File \"/usr/local/lib/python3.10/site-packages/typer/main.py\", line 311, in __call__\n    return get_command(self)(*args, **kwargs)\n", "  File \"/usr/local/lib/python3.10/site-packages/click/core.py\", line 1130, in __call__\n    return self.main(*args, **kwargs)\n", "  File \"/usr/local/lib/python3.10/site-packages/typer/core.py\", line 778, in main\n    return _main(\n", "  File \"/usr/local/lib/python3.10/site-packages/typer/core.py\", line 216, in _main\n    rv = self.invoke(ctx)\n", "  File \"/usr/local/lib/python3.10/site-packages/click/core.py\", line 1657, in invoke\n    return _process_result(sub_ctx.command.invoke(sub_ctx))\n", "  File \"/usr/local/lib/python3.10/site-packages/click/core.py\", line 1404, in invoke\n    return ctx.invoke(self.callback, **ctx.params)\n", "  File \"/usr/local/lib/python3.10/site-packages/click/core.py\", line 760, in invoke\n    return __callback(*args, **kwargs)\n", "  File \"/usr/local/lib/python3.10/site-packages/typer/main.py\", line 683, in wrapper\n    return callback(**use_params)  # type: ignore\n", "  File \"/usr/local/lib/python3.10/site-packages/mage_ai/cli/main.py\", line 163, in start\n    start_server(\n", "  File \"/usr/local/lib/python3.10/site-packages/mage_ai/server/server.py\", line 659, in start_server\n    scheduler_manager.start_scheduler()\n", "  File \"/usr/local/lib/python3.10/site-packages/mage_ai/server/scheduler_manager.py\", line 87, in start_scheduler\n    proc.start()\n", "  File \"/usr/local/lib/python3.10/multiprocessing/process.py\", line 121, in start\n    self._popen = self._Popen(self)\n", "  File \"/usr/local/lib/python3.10/multiprocessing/context.py\", line 224, in _Popen\n    return _default_context.get_context().Process._Popen(process_obj)\n", "  File \"/usr/local/lib/python3.10/multiprocessing/context.py\", line 281, in _Popen\n    return Popen(process_obj)\n", "  File \"/usr/local/lib/python3.10/multiprocessing/popen_fork.py\", line 19, in __init__\n    self._launch(process_obj)\n", "  File \"/usr/local/lib/python3.10/multiprocessing/popen_fork.py\", line 71, in _launch\n    code = process_obj._bootstrap(parent_sentinel=child_r)\n", "  File \"/usr/local/lib/python3.10/multiprocessing/process.py\", line 314, in _bootstrap\n    self.run()\n", "  File \"/usr/local/lib/python3.10/multiprocessing/process.py\", line 108, in run\n    self._target(*self._args, **self._kwargs)\n", "  File \"/usr/local/lib/python3.10/site-packages/mage_ai/orchestration/db/process.py\", line 15, in start_session_and_run\n    results = target(*args)\n", "  File \"/usr/local/lib/python3.10/site-packages/mage_ai/server/scheduler_manager.py\", line 50, in run_scheduler\n    LoopTimeTrigger().start()\n", "  File \"/usr/local/lib/python3.10/site-packages/mage_ai/orchestration/triggers/loop_time_trigger.py\", line 14, in start\n    self.run()\n", "  File \"/usr/local/lib/python3.10/site-packages/mage_ai/orchestration/triggers/time_trigger.py\", line 11, in run\n    schedule_all()\n", "  File \"/usr/local/lib/python3.10/site-packages/mage_ai/orchestration/pipeline_scheduler_original.py\", line 1580, in schedule_all\n    PipelineScheduler(r).schedule()\n", "  File \"/usr/local/lib/python3.10/site-packages/mage_ai/orchestration/db/__init__.py\", line 149, in func_with_rollback\n    return func(*args, **kwargs)\n", "  File \"/usr/local/lib/python3.10/site-packages/mage_ai/orchestration/pipeline_scheduler_original.py\", line 319, in schedule\n    self.__schedule_blocks(block_runs)\n", "  File \"/usr/local/lib/python3.10/site-packages/mage_ai/orchestration/pipeline_scheduler_original.py\", line 581, in __schedule_blocks\n    job_manager.add_job(\n", "  File \"/usr/local/lib/python3.10/site-packages/mage_ai/orchestration/job_manager.py\", line 27, in add_job\n    self.queue.enqueue(job_id, target, *args, **kwargs)\n", "  File \"/usr/local/lib/python3.10/site-packages/mage_ai/orchestration/queue/process_queue.py\", line 107, in enqueue\n    self.start_worker_pool()\n", "  File \"/usr/local/lib/python3.10/site-packages/mage_ai/orchestration/queue/process_queue.py\", line 173, in start_worker_pool\n    self.worker_pool_proc.start()\n", "  File \"/usr/local/lib/python3.10/multiprocessing/process.py\", line 121, in start\n    self._popen = self._Popen(self)\n", "  File \"/usr/local/lib/python3.10/multiprocessing/context.py\", line 224, in _Popen\n    return _default_context.get_context().Process._Popen(process_obj)\n", "  File \"/usr/local/lib/python3.10/multiprocessing/context.py\", line 281, in _Popen\n    return Popen(process_obj)\n", "  File \"/usr/local/lib/python3.10/multiprocessing/popen_fork.py\", line 19, in __init__\n    self._launch(process_obj)\n", "  File \"/usr/local/lib/python3.10/multiprocessing/popen_fork.py\", line 71, in _launch\n    code = process_obj._bootstrap(parent_sentinel=child_r)\n", "  File \"/usr/local/lib/python3.10/multiprocessing/process.py\", line 314, in _bootstrap\n    self.run()\n", "  File \"/usr/local/lib/python3.10/multiprocessing/process.py\", line 108, in run\n    self._target(*self._args, **self._kwargs)\n", "  File \"/usr/local/lib/python3.10/site-packages/mage_ai/orchestration/queue/process_queue.py\", line 275, in poll_job_and_execute\n    worker.start()\n", "  File \"/usr/local/lib/python3.10/multiprocessing/process.py\", line 121, in start\n    self._popen = self._Popen(self)\n", "  File \"/usr/local/lib/python3.10/multiprocessing/context.py\", line 224, in _Popen\n    return _default_context.get_context().Process._Popen(process_obj)\n", "  File \"/usr/local/lib/python3.10/multiprocessing/context.py\", line 281, in _Popen\n    return Popen(process_obj)\n", "  File \"/usr/local/lib/python3.10/multiprocessing/popen_fork.py\", line 19, in __init__\n    self._launch(process_obj)\n", "  File \"/usr/local/lib/python3.10/multiprocessing/popen_fork.py\", line 71, in _launch\n    code = process_obj._bootstrap(parent_sentinel=child_r)\n", "  File \"/usr/local/lib/python3.10/multiprocessing/process.py\", line 314, in _bootstrap\n    self.run()\n", "  File \"/usr/local/lib/python3.10/site-packages/newrelic/api/background_task.py\", line 117, in wrapper\n    return wrapped(*args, **kwargs)\n", "  File \"/usr/local/lib/python3.10/site-packages/mage_ai/orchestration/queue/process_queue.py\", line 240, in run\n    start_session_and_run(args[1], *args[2], **args[3])\n", "  File \"/usr/local/lib/python3.10/site-packages/mage_ai/orchestration/db/process.py\", line 15, in start_session_and_run\n    results = target(*args)\n", "  File \"/usr/local/lib/python3.10/site-packages/mage_ai/orchestration/pipeline_scheduler_original.py\", line 1105, in run_block\n    return ExecutorFactory.get_block_executor(\n", "  File \"/usr/local/lib/python3.10/site-packages/mage_ai/data_preparation/executors/block_executor.py\", line 621, in execute\n    on_failure(\n", "  File \"/usr/local/lib/python3.10/site-packages/mage_ai/orchestration/db/__init__.py\", line 149, in func_with_rollback\n    return func(*args, **kwargs)\n", "  File \"/usr/local/lib/python3.10/site-packages/mage_ai/orchestration/pipeline_scheduler_original.py\", line 415, in on_block_failure\n    self.logger.exception(\n", "  File \"/usr/local/lib/python3.10/site-packages/mage_ai/data_preparation/logging/logger.py\", line 30, in exception\n    self.__send_message('exception', message, **kwargs)\n", "  File \"/usr/local/lib/python3.10/site-packages/mage_ai/data_preparation/logging/logger.py\", line 59, in __send_message\n    data['error_stack'] = traceback.format_stack(),\n"]], "error_stacktrace": ["No connection currently open. Open a new connection to access this property."]}
Traceback (most recent call last):
  File "/usr/local/lib/python3.10/site-packages/mage_ai/io/base.py", line 345, in conn
    return self._ctx
AttributeError: 'Postgres' object has no attribute '_ctx'

During handling of the above exception, another exception occurred:

Traceback (most recent call last):
  File "/usr/local/lib/python3.10/site-packages/mage_ai/data_preparation/executors/block_executor.py", line 605, in execute
    result = __execute_with_retry()
  File "/usr/local/lib/python3.10/site-packages/mage_ai/shared/retry.py", line 54, in retry_func
    raise e
  File "/usr/local/lib/python3.10/site-packages/mage_ai/shared/retry.py", line 38, in retry_func
    return func(*args, **kwargs)
  File "/usr/local/lib/python3.10/site-packages/mage_ai/data_preparation/executors/block_executor.py", line 578, in __execute_with_retry
    return self._execute(
  File "/usr/local/lib/python3.10/site-packages/mage_ai/data_preparation/executors/block_executor.py", line 1052, in _execute
    result = self.block.execute_sync(
  File "/usr/local/lib/python3.10/site-packages/mage_ai/data_preparation/models/block/__init__.py", line 1285, in execute_sync
    raise err
  File "/usr/local/lib/python3.10/site-packages/mage_ai/data_preparation/models/block/__init__.py", line 1194, in execute_sync
    output = self.execute_block(
  File "/usr/local/lib/python3.10/site-packages/mage_ai/data_preparation/models/block/__init__.py", line 1509, in execute_block
    outputs = self._execute_block(
  File "/usr/local/lib/python3.10/site-packages/mage_ai/data_preparation/models/block/__init__.py", line 1665, in _execute_block
    outputs = self.execute_block_function(
  File "/usr/local/lib/python3.10/site-packages/mage_ai/data_preparation/models/block/__init__.py", line 1704, in execute_block_function
    output = block_function_updated(*input_vars, **global_vars)
  File "<string>", line 25, in export_data_to_postgres
  File "/usr/local/lib/python3.10/site-packages/mage_ai/io/sql.py", line 359, in export
    __process()
  File "/usr/local/lib/python3.10/site-packages/mage_ai/io/sql.py", line 292, in __process
    table_exists = self.table_exists(schema_name, table_name)
  File "/usr/local/lib/python3.10/site-packages/mage_ai/io/postgres.py", line 166, in table_exists
    with self.conn.cursor() as cur:
  File "/usr/local/lib/python3.10/site-packages/mage_ai/io/base.py", line 347, in conn
    raise ConnectionError(
ConnectionError: No connection currently open. Open a new connection to access this property.
2024-03-26T17:49:52 {"cpu": 0.06103515625, "cpu_total": 16, "cpu_usage": 0.003814697265625, "memory": 1950.0, "memory_total": 9698.0, "memory_usage": 0.20107238605898123, "pipeline_run_id": 27, "pipeline_schedule_id": 4, "pipeline_uuid": "fore_to_postgres", "hostname": "0db69d3fbb20", "level": "INFO", "message": "Pipeline fore_to_postgres for run 27 in schedule 4 is alive.", "timestamp": 1711475392.678611, "uuid": "c66d2d3f51004e41903ebbf473be8464"}
