2024-03-26T18:08:53 {"block_run_id": 78, "block_uuid": "fore_to_postgres", "pipeline_run_id": 26, "pipeline_schedule_id": 4, "pipeline_uuid": "fore_to_postgres", "hostname": "9c95c407929b", "block_type": "data_exporter", "level": "INFO", "message": "Start executing block with BlockExecutor.", "timestamp": 1711476533.329152, "uuid": "4216026569234b1890b527be7764a787"}
2024-03-26T18:08:53 {"block_run_id": 78, "block_uuid": "fore_to_postgres", "pipeline_run_id": 26, "pipeline_schedule_id": 4, "pipeline_uuid": "fore_to_postgres", "hostname": "9c95c407929b", "block_type": "data_exporter", "level": "INFO", "message": "Postgres initialized", "timestamp": 1711476533.572592, "uuid": "aa6d1254f1bc4240b67ba741008c0d16"}
2024-03-26T18:08:53 {"block_run_id": 78, "block_uuid": "fore_to_postgres", "pipeline_run_id": 26, "pipeline_schedule_id": 4, "pipeline_uuid": "fore_to_postgres", "hostname": "9c95c407929b", "block_type": "data_exporter", "level": "INFO", "message": "\u2514\u2500 Opening connection to PostgreSQL database...", "timestamp": 1711476533.575312, "uuid": "bdc3c0efddb745e7a8141262cc793700"}
2024-03-26T18:08:58 {"block_run_id": 78, "block_uuid": "fore_to_postgres", "pipeline_run_id": 26, "pipeline_schedule_id": 4, "pipeline_uuid": "fore_to_postgres", "hostname": "9c95c407929b", "block_type": "data_exporter", "level": "INFO", "message": "Traceback (most recent call last):", "timestamp": 1711476538.659915, "uuid": "54989e66326d40e797642e5a557b7799"}
2024-03-26T18:08:58 {"block_run_id": 78, "block_uuid": "fore_to_postgres", "pipeline_run_id": 26, "pipeline_schedule_id": 4, "pipeline_uuid": "fore_to_postgres", "hostname": "9c95c407929b", "block_type": "data_exporter", "level": "INFO", "message": "  File \"/usr/local/lib/python3.10/site-packages/mage_ai/io/postgres.py\", line 145, in open", "timestamp": 1711476538.661426, "uuid": "588f88f36fae48e7b6f872d7882f198f"}
2024-03-26T18:08:58 {"block_run_id": 78, "block_uuid": "fore_to_postgres", "pipeline_run_id": 26, "pipeline_schedule_id": 4, "pipeline_uuid": "fore_to_postgres", "hostname": "9c95c407929b", "block_type": "data_exporter", "level": "INFO", "message": "    self._ctx = connect(**connect_opts)", "timestamp": 1711476538.663729, "uuid": "bcea77251a2e42e9a2983b5e3e72736e"}
2024-03-26T18:08:58 {"block_run_id": 78, "block_uuid": "fore_to_postgres", "pipeline_run_id": 26, "pipeline_schedule_id": 4, "pipeline_uuid": "fore_to_postgres", "hostname": "9c95c407929b", "block_type": "data_exporter", "level": "INFO", "message": "  File \"/usr/local/lib/python3.10/site-packages/psycopg2/__init__.py\", line 122, in connect", "timestamp": 1711476538.665623, "uuid": "cef1a868dc7740449badd4f8f4aa7099"}
2024-03-26T18:08:58 {"block_run_id": 78, "block_uuid": "fore_to_postgres", "pipeline_run_id": 26, "pipeline_schedule_id": 4, "pipeline_uuid": "fore_to_postgres", "hostname": "9c95c407929b", "block_type": "data_exporter", "level": "INFO", "message": "    conn = _connect(dsn, connection_factory=connection_factory, **kwasync)", "timestamp": 1711476538.667928, "uuid": "e0d1a510526c450390a262fa19a1969b"}
2024-03-26T18:08:58 {"block_run_id": 78, "block_uuid": "fore_to_postgres", "pipeline_run_id": 26, "pipeline_schedule_id": 4, "pipeline_uuid": "fore_to_postgres", "hostname": "9c95c407929b", "block_type": "data_exporter", "level": "INFO", "message": "psycopg2.OperationalError: connection to server at \"pgdatabase\" (172.24.0.3), port 5432 failed: Connection refused", "timestamp": 1711476538.670131, "uuid": "4792d28fda3e46c1bcbbcda5fdce092a"}
2024-03-26T18:08:58 {"block_run_id": 78, "block_uuid": "fore_to_postgres", "pipeline_run_id": 26, "pipeline_schedule_id": 4, "pipeline_uuid": "fore_to_postgres", "hostname": "9c95c407929b", "block_type": "data_exporter", "level": "INFO", "message": "\tIs the server running on that host and accepting TCP/IP connections?", "timestamp": 1711476538.672077, "uuid": "1cc7ab51cfbd429f8858b574ed233721"}
2024-03-26T18:08:58 {"block_run_id": 78, "block_uuid": "fore_to_postgres", "pipeline_run_id": 26, "pipeline_schedule_id": 4, "pipeline_uuid": "fore_to_postgres", "hostname": "9c95c407929b", "block_type": "data_exporter", "level": "INFO", "message": "DONE", "timestamp": 1711476538.67381, "uuid": "5831bc55791f455c8706e0b68f8dbf4f"}
2024-03-26T18:08:58 {"block_run_id": 78, "block_uuid": "fore_to_postgres", "pipeline_run_id": 26, "pipeline_schedule_id": 4, "pipeline_uuid": "fore_to_postgres", "hostname": "9c95c407929b", "block_type": "data_exporter", "level": "INFO", "message": "", "timestamp": 1711476538.688688, "uuid": "54590c20395445aca2a2e3637f4edd63"}
2024-03-26T18:08:58 {"block_run_id": 78, "block_uuid": "fore_to_postgres", "pipeline_run_id": 26, "pipeline_schedule_id": 4, "pipeline_uuid": "fore_to_postgres", "hostname": "9c95c407929b", "block_type": "data_exporter", "level": "INFO", "message": "\u251c\u2500", "timestamp": 1711476538.689576, "uuid": "d44ca734afa04dc1aaaf51ca51821897"}
2024-03-26T18:08:58 {"block_run_id": 78, "block_uuid": "fore_to_postgres", "pipeline_run_id": 26, "pipeline_schedule_id": 4, "pipeline_uuid": "fore_to_postgres", "hostname": "9c95c407929b", "block_type": "data_exporter", "level": "INFO", "message": "\u2514\u2500 Exporting data to 'forecast_data.scraped_forecasts_staging'...", "timestamp": 1711476538.690934, "uuid": "060328f3ac1c4852ade64cc8e90a76f1"}
2024-03-26T18:08:58 {"block_run_id": 78, "block_uuid": "fore_to_postgres", "pipeline_run_id": 26, "pipeline_schedule_id": 4, "pipeline_uuid": "fore_to_postgres", "hostname": "9c95c407929b", "block_type": "data_exporter", "level": "WARNING", "message": "Exception thrown when attempting to run <function BlockExecutor.execute.<locals>.__execute_with_retry at 0x7f1b68118280>, attempt 1 of 1", "timestamp": 1711476538.692917, "uuid": "2ff5427b44764ac98b4ce4db40fdfd49", "error": ["Traceback (most recent call last):\n  File \"/usr/local/lib/python3.10/site-packages/mage_ai/io/base.py\", line 345, in conn\n    return self._ctx\nAttributeError: 'Postgres' object has no attribute '_ctx'\n\nDuring handling of the above exception, another exception occurred:\n\nTraceback (most recent call last):\n  File \"/usr/local/lib/python3.10/site-packages/mage_ai/shared/retry.py\", line 38, in retry_func\n    return func(*args, **kwargs)\n  File \"/usr/local/lib/python3.10/site-packages/mage_ai/data_preparation/executors/block_executor.py\", line 578, in __execute_with_retry\n    return self._execute(\n  File \"/usr/local/lib/python3.10/site-packages/mage_ai/data_preparation/executors/block_executor.py\", line 1052, in _execute\n    result = self.block.execute_sync(\n  File \"/usr/local/lib/python3.10/site-packages/mage_ai/data_preparation/models/block/__init__.py\", line 1285, in execute_sync\n    raise err\n  File \"/usr/local/lib/python3.10/site-packages/mage_ai/data_preparation/models/block/__init__.py\", line 1194, in execute_sync\n    output = self.execute_block(\n  File \"/usr/local/lib/python3.10/site-packages/mage_ai/data_preparation/models/block/__init__.py\", line 1509, in execute_block\n    outputs = self._execute_block(\n  File \"/usr/local/lib/python3.10/site-packages/mage_ai/data_preparation/models/block/__init__.py\", line 1665, in _execute_block\n    outputs = self.execute_block_function(\n  File \"/usr/local/lib/python3.10/site-packages/mage_ai/data_preparation/models/block/__init__.py\", line 1704, in execute_block_function\n    output = block_function_updated(*input_vars, **global_vars)\n  File \"<string>\", line 25, in export_data_to_postgres\n  File \"/usr/local/lib/python3.10/site-packages/mage_ai/io/sql.py\", line 359, in export\n    __process()\n  File \"/usr/local/lib/python3.10/site-packages/mage_ai/io/sql.py\", line 292, in __process\n    table_exists = self.table_exists(schema_name, table_name)\n  File \"/usr/local/lib/python3.10/site-packages/mage_ai/io/postgres.py\", line 166, in table_exists\n    with self.conn.cursor() as cur:\n  File \"/usr/local/lib/python3.10/site-packages/mage_ai/io/base.py\", line 347, in conn\n    raise ConnectionError(\nConnectionError: No connection currently open. Open a new connection to access this property.\n"], "error_stack": [["  File \"/usr/local/bin/mage\", line 8, in <module>\n    sys.exit(app())\n", "  File \"/usr/local/lib/python3.10/site-packages/typer/main.py\", line 311, in __call__\n    return get_command(self)(*args, **kwargs)\n", "  File \"/usr/local/lib/python3.10/site-packages/click/core.py\", line 1130, in __call__\n    return self.main(*args, **kwargs)\n", "  File \"/usr/local/lib/python3.10/site-packages/typer/core.py\", line 778, in main\n    return _main(\n", "  File \"/usr/local/lib/python3.10/site-packages/typer/core.py\", line 216, in _main\n    rv = self.invoke(ctx)\n", "  File \"/usr/local/lib/python3.10/site-packages/click/core.py\", line 1657, in invoke\n    return _process_result(sub_ctx.command.invoke(sub_ctx))\n", "  File \"/usr/local/lib/python3.10/site-packages/click/core.py\", line 1404, in invoke\n    return ctx.invoke(self.callback, **ctx.params)\n", "  File \"/usr/local/lib/python3.10/site-packages/click/core.py\", line 760, in invoke\n    return __callback(*args, **kwargs)\n", "  File \"/usr/local/lib/python3.10/site-packages/typer/main.py\", line 683, in wrapper\n    return callback(**use_params)  # type: ignore\n", "  File \"/usr/local/lib/python3.10/site-packages/mage_ai/cli/main.py\", line 163, in start\n    start_server(\n", "  File \"/usr/local/lib/python3.10/site-packages/mage_ai/server/server.py\", line 659, in start_server\n    scheduler_manager.start_scheduler()\n", "  File \"/usr/local/lib/python3.10/site-packages/mage_ai/server/scheduler_manager.py\", line 87, in start_scheduler\n    proc.start()\n", "  File \"/usr/local/lib/python3.10/multiprocessing/process.py\", line 121, in start\n    self._popen = self._Popen(self)\n", "  File \"/usr/local/lib/python3.10/multiprocessing/context.py\", line 224, in _Popen\n    return _default_context.get_context().Process._Popen(process_obj)\n", "  File \"/usr/local/lib/python3.10/multiprocessing/context.py\", line 281, in _Popen\n    return Popen(process_obj)\n", "  File \"/usr/local/lib/python3.10/multiprocessing/popen_fork.py\", line 19, in __init__\n    self._launch(process_obj)\n", "  File \"/usr/local/lib/python3.10/multiprocessing/popen_fork.py\", line 71, in _launch\n    code = process_obj._bootstrap(parent_sentinel=child_r)\n", "  File \"/usr/local/lib/python3.10/multiprocessing/process.py\", line 314, in _bootstrap\n    self.run()\n", "  File \"/usr/local/lib/python3.10/multiprocessing/process.py\", line 108, in run\n    self._target(*self._args, **self._kwargs)\n", "  File \"/usr/local/lib/python3.10/site-packages/mage_ai/orchestration/db/process.py\", line 15, in start_session_and_run\n    results = target(*args)\n", "  File \"/usr/local/lib/python3.10/site-packages/mage_ai/server/scheduler_manager.py\", line 50, in run_scheduler\n    LoopTimeTrigger().start()\n", "  File \"/usr/local/lib/python3.10/site-packages/mage_ai/orchestration/triggers/loop_time_trigger.py\", line 14, in start\n    self.run()\n", "  File \"/usr/local/lib/python3.10/site-packages/mage_ai/orchestration/triggers/time_trigger.py\", line 11, in run\n    schedule_all()\n", "  File \"/usr/local/lib/python3.10/site-packages/mage_ai/orchestration/pipeline_scheduler_original.py\", line 1580, in schedule_all\n    PipelineScheduler(r).schedule()\n", "  File \"/usr/local/lib/python3.10/site-packages/mage_ai/orchestration/db/__init__.py\", line 149, in func_with_rollback\n    return func(*args, **kwargs)\n", "  File \"/usr/local/lib/python3.10/site-packages/mage_ai/orchestration/pipeline_scheduler_original.py\", line 319, in schedule\n    self.__schedule_blocks(block_runs)\n", "  File \"/usr/local/lib/python3.10/site-packages/mage_ai/orchestration/pipeline_scheduler_original.py\", line 581, in __schedule_blocks\n    job_manager.add_job(\n", "  File \"/usr/local/lib/python3.10/site-packages/mage_ai/orchestration/job_manager.py\", line 27, in add_job\n    self.queue.enqueue(job_id, target, *args, **kwargs)\n", "  File \"/usr/local/lib/python3.10/site-packages/mage_ai/orchestration/queue/process_queue.py\", line 107, in enqueue\n    self.start_worker_pool()\n", "  File \"/usr/local/lib/python3.10/site-packages/mage_ai/orchestration/queue/process_queue.py\", line 173, in start_worker_pool\n    self.worker_pool_proc.start()\n", "  File \"/usr/local/lib/python3.10/multiprocessing/process.py\", line 121, in start\n    self._popen = self._Popen(self)\n", "  File \"/usr/local/lib/python3.10/multiprocessing/context.py\", line 224, in _Popen\n    return _default_context.get_context().Process._Popen(process_obj)\n", "  File \"/usr/local/lib/python3.10/multiprocessing/context.py\", line 281, in _Popen\n    return Popen(process_obj)\n", "  File \"/usr/local/lib/python3.10/multiprocessing/popen_fork.py\", line 19, in __init__\n    self._launch(process_obj)\n", "  File \"/usr/local/lib/python3.10/multiprocessing/popen_fork.py\", line 71, in _launch\n    code = process_obj._bootstrap(parent_sentinel=child_r)\n", "  File \"/usr/local/lib/python3.10/multiprocessing/process.py\", line 314, in _bootstrap\n    self.run()\n", "  File \"/usr/local/lib/python3.10/multiprocessing/process.py\", line 108, in run\n    self._target(*self._args, **self._kwargs)\n", "  File \"/usr/local/lib/python3.10/site-packages/mage_ai/orchestration/queue/process_queue.py\", line 275, in poll_job_and_execute\n    worker.start()\n", "  File \"/usr/local/lib/python3.10/multiprocessing/process.py\", line 121, in start\n    self._popen = self._Popen(self)\n", "  File \"/usr/local/lib/python3.10/multiprocessing/context.py\", line 224, in _Popen\n    return _default_context.get_context().Process._Popen(process_obj)\n", "  File \"/usr/local/lib/python3.10/multiprocessing/context.py\", line 281, in _Popen\n    return Popen(process_obj)\n", "  File \"/usr/local/lib/python3.10/multiprocessing/popen_fork.py\", line 19, in __init__\n    self._launch(process_obj)\n", "  File \"/usr/local/lib/python3.10/multiprocessing/popen_fork.py\", line 71, in _launch\n    code = process_obj._bootstrap(parent_sentinel=child_r)\n", "  File \"/usr/local/lib/python3.10/multiprocessing/process.py\", line 314, in _bootstrap\n    self.run()\n", "  File \"/usr/local/lib/python3.10/site-packages/newrelic/api/background_task.py\", line 117, in wrapper\n    return wrapped(*args, **kwargs)\n", "  File \"/usr/local/lib/python3.10/site-packages/mage_ai/orchestration/queue/process_queue.py\", line 240, in run\n    start_session_and_run(args[1], *args[2], **args[3])\n", "  File \"/usr/local/lib/python3.10/site-packages/mage_ai/orchestration/db/process.py\", line 15, in start_session_and_run\n    results = target(*args)\n", "  File \"/usr/local/lib/python3.10/site-packages/mage_ai/orchestration/pipeline_scheduler_original.py\", line 1105, in run_block\n    return ExecutorFactory.get_block_executor(\n", "  File \"/usr/local/lib/python3.10/site-packages/mage_ai/data_preparation/executors/block_executor.py\", line 605, in execute\n    result = __execute_with_retry()\n", "  File \"/usr/local/lib/python3.10/site-packages/mage_ai/shared/retry.py\", line 46, in retry_func\n    logger.warning(\n", "  File \"/usr/local/lib/python3.10/site-packages/mage_ai/data_preparation/logging/logger.py\", line 39, in warning\n    self.__send_message('warning', message, **kwargs)\n", "  File \"/usr/local/lib/python3.10/site-packages/mage_ai/data_preparation/logging/logger.py\", line 59, in __send_message\n    data['error_stack'] = traceback.format_stack(),\n"]], "error_stacktrace": ["No connection currently open. Open a new connection to access this property."]}
2024-03-26T18:08:58 {"block_run_id": 78, "block_uuid": "fore_to_postgres", "pipeline_run_id": 26, "pipeline_schedule_id": 4, "pipeline_uuid": "fore_to_postgres", "hostname": "9c95c407929b", "block_type": "data_exporter", "level": "EXCEPTION", "message": "Failed to execute block fore_to_postgres", "timestamp": 1711476538.703551, "uuid": "9f5859d316914586871f780f1010d4ed", "error": ["Traceback (most recent call last):\n  File \"/usr/local/lib/python3.10/site-packages/mage_ai/io/base.py\", line 345, in conn\n    return self._ctx\nAttributeError: 'Postgres' object has no attribute '_ctx'\n\nDuring handling of the above exception, another exception occurred:\n\nTraceback (most recent call last):\n  File \"/usr/local/lib/python3.10/site-packages/mage_ai/data_preparation/executors/block_executor.py\", line 605, in execute\n    result = __execute_with_retry()\n  File \"/usr/local/lib/python3.10/site-packages/mage_ai/shared/retry.py\", line 54, in retry_func\n    raise e\n  File \"/usr/local/lib/python3.10/site-packages/mage_ai/shared/retry.py\", line 38, in retry_func\n    return func(*args, **kwargs)\n  File \"/usr/local/lib/python3.10/site-packages/mage_ai/data_preparation/executors/block_executor.py\", line 578, in __execute_with_retry\n    return self._execute(\n  File \"/usr/local/lib/python3.10/site-packages/mage_ai/data_preparation/executors/block_executor.py\", line 1052, in _execute\n    result = self.block.execute_sync(\n  File \"/usr/local/lib/python3.10/site-packages/mage_ai/data_preparation/models/block/__init__.py\", line 1285, in execute_sync\n    raise err\n  File \"/usr/local/lib/python3.10/site-packages/mage_ai/data_preparation/models/block/__init__.py\", line 1194, in execute_sync\n    output = self.execute_block(\n  File \"/usr/local/lib/python3.10/site-packages/mage_ai/data_preparation/models/block/__init__.py\", line 1509, in execute_block\n    outputs = self._execute_block(\n  File \"/usr/local/lib/python3.10/site-packages/mage_ai/data_preparation/models/block/__init__.py\", line 1665, in _execute_block\n    outputs = self.execute_block_function(\n  File \"/usr/local/lib/python3.10/site-packages/mage_ai/data_preparation/models/block/__init__.py\", line 1704, in execute_block_function\n    output = block_function_updated(*input_vars, **global_vars)\n  File \"<string>\", line 25, in export_data_to_postgres\n  File \"/usr/local/lib/python3.10/site-packages/mage_ai/io/sql.py\", line 359, in export\n    __process()\n  File \"/usr/local/lib/python3.10/site-packages/mage_ai/io/sql.py\", line 292, in __process\n    table_exists = self.table_exists(schema_name, table_name)\n  File \"/usr/local/lib/python3.10/site-packages/mage_ai/io/postgres.py\", line 166, in table_exists\n    with self.conn.cursor() as cur:\n  File \"/usr/local/lib/python3.10/site-packages/mage_ai/io/base.py\", line 347, in conn\n    raise ConnectionError(\nConnectionError: No connection currently open. Open a new connection to access this property.\n"], "error_stack": [["  File \"/usr/local/bin/mage\", line 8, in <module>\n    sys.exit(app())\n", "  File \"/usr/local/lib/python3.10/site-packages/typer/main.py\", line 311, in __call__\n    return get_command(self)(*args, **kwargs)\n", "  File \"/usr/local/lib/python3.10/site-packages/click/core.py\", line 1130, in __call__\n    return self.main(*args, **kwargs)\n", "  File \"/usr/local/lib/python3.10/site-packages/typer/core.py\", line 778, in main\n    return _main(\n", "  File \"/usr/local/lib/python3.10/site-packages/typer/core.py\", line 216, in _main\n    rv = self.invoke(ctx)\n", "  File \"/usr/local/lib/python3.10/site-packages/click/core.py\", line 1657, in invoke\n    return _process_result(sub_ctx.command.invoke(sub_ctx))\n", "  File \"/usr/local/lib/python3.10/site-packages/click/core.py\", line 1404, in invoke\n    return ctx.invoke(self.callback, **ctx.params)\n", "  File \"/usr/local/lib/python3.10/site-packages/click/core.py\", line 760, in invoke\n    return __callback(*args, **kwargs)\n", "  File \"/usr/local/lib/python3.10/site-packages/typer/main.py\", line 683, in wrapper\n    return callback(**use_params)  # type: ignore\n", "  File \"/usr/local/lib/python3.10/site-packages/mage_ai/cli/main.py\", line 163, in start\n    start_server(\n", "  File \"/usr/local/lib/python3.10/site-packages/mage_ai/server/server.py\", line 659, in start_server\n    scheduler_manager.start_scheduler()\n", "  File \"/usr/local/lib/python3.10/site-packages/mage_ai/server/scheduler_manager.py\", line 87, in start_scheduler\n    proc.start()\n", "  File \"/usr/local/lib/python3.10/multiprocessing/process.py\", line 121, in start\n    self._popen = self._Popen(self)\n", "  File \"/usr/local/lib/python3.10/multiprocessing/context.py\", line 224, in _Popen\n    return _default_context.get_context().Process._Popen(process_obj)\n", "  File \"/usr/local/lib/python3.10/multiprocessing/context.py\", line 281, in _Popen\n    return Popen(process_obj)\n", "  File \"/usr/local/lib/python3.10/multiprocessing/popen_fork.py\", line 19, in __init__\n    self._launch(process_obj)\n", "  File \"/usr/local/lib/python3.10/multiprocessing/popen_fork.py\", line 71, in _launch\n    code = process_obj._bootstrap(parent_sentinel=child_r)\n", "  File \"/usr/local/lib/python3.10/multiprocessing/process.py\", line 314, in _bootstrap\n    self.run()\n", "  File \"/usr/local/lib/python3.10/multiprocessing/process.py\", line 108, in run\n    self._target(*self._args, **self._kwargs)\n", "  File \"/usr/local/lib/python3.10/site-packages/mage_ai/orchestration/db/process.py\", line 15, in start_session_and_run\n    results = target(*args)\n", "  File \"/usr/local/lib/python3.10/site-packages/mage_ai/server/scheduler_manager.py\", line 50, in run_scheduler\n    LoopTimeTrigger().start()\n", "  File \"/usr/local/lib/python3.10/site-packages/mage_ai/orchestration/triggers/loop_time_trigger.py\", line 14, in start\n    self.run()\n", "  File \"/usr/local/lib/python3.10/site-packages/mage_ai/orchestration/triggers/time_trigger.py\", line 11, in run\n    schedule_all()\n", "  File \"/usr/local/lib/python3.10/site-packages/mage_ai/orchestration/pipeline_scheduler_original.py\", line 1580, in schedule_all\n    PipelineScheduler(r).schedule()\n", "  File \"/usr/local/lib/python3.10/site-packages/mage_ai/orchestration/db/__init__.py\", line 149, in func_with_rollback\n    return func(*args, **kwargs)\n", "  File \"/usr/local/lib/python3.10/site-packages/mage_ai/orchestration/pipeline_scheduler_original.py\", line 319, in schedule\n    self.__schedule_blocks(block_runs)\n", "  File \"/usr/local/lib/python3.10/site-packages/mage_ai/orchestration/pipeline_scheduler_original.py\", line 581, in __schedule_blocks\n    job_manager.add_job(\n", "  File \"/usr/local/lib/python3.10/site-packages/mage_ai/orchestration/job_manager.py\", line 27, in add_job\n    self.queue.enqueue(job_id, target, *args, **kwargs)\n", "  File \"/usr/local/lib/python3.10/site-packages/mage_ai/orchestration/queue/process_queue.py\", line 107, in enqueue\n    self.start_worker_pool()\n", "  File \"/usr/local/lib/python3.10/site-packages/mage_ai/orchestration/queue/process_queue.py\", line 173, in start_worker_pool\n    self.worker_pool_proc.start()\n", "  File \"/usr/local/lib/python3.10/multiprocessing/process.py\", line 121, in start\n    self._popen = self._Popen(self)\n", "  File \"/usr/local/lib/python3.10/multiprocessing/context.py\", line 224, in _Popen\n    return _default_context.get_context().Process._Popen(process_obj)\n", "  File \"/usr/local/lib/python3.10/multiprocessing/context.py\", line 281, in _Popen\n    return Popen(process_obj)\n", "  File \"/usr/local/lib/python3.10/multiprocessing/popen_fork.py\", line 19, in __init__\n    self._launch(process_obj)\n", "  File \"/usr/local/lib/python3.10/multiprocessing/popen_fork.py\", line 71, in _launch\n    code = process_obj._bootstrap(parent_sentinel=child_r)\n", "  File \"/usr/local/lib/python3.10/multiprocessing/process.py\", line 314, in _bootstrap\n    self.run()\n", "  File \"/usr/local/lib/python3.10/multiprocessing/process.py\", line 108, in run\n    self._target(*self._args, **self._kwargs)\n", "  File \"/usr/local/lib/python3.10/site-packages/mage_ai/orchestration/queue/process_queue.py\", line 275, in poll_job_and_execute\n    worker.start()\n", "  File \"/usr/local/lib/python3.10/multiprocessing/process.py\", line 121, in start\n    self._popen = self._Popen(self)\n", "  File \"/usr/local/lib/python3.10/multiprocessing/context.py\", line 224, in _Popen\n    return _default_context.get_context().Process._Popen(process_obj)\n", "  File \"/usr/local/lib/python3.10/multiprocessing/context.py\", line 281, in _Popen\n    return Popen(process_obj)\n", "  File \"/usr/local/lib/python3.10/multiprocessing/popen_fork.py\", line 19, in __init__\n    self._launch(process_obj)\n", "  File \"/usr/local/lib/python3.10/multiprocessing/popen_fork.py\", line 71, in _launch\n    code = process_obj._bootstrap(parent_sentinel=child_r)\n", "  File \"/usr/local/lib/python3.10/multiprocessing/process.py\", line 314, in _bootstrap\n    self.run()\n", "  File \"/usr/local/lib/python3.10/site-packages/newrelic/api/background_task.py\", line 117, in wrapper\n    return wrapped(*args, **kwargs)\n", "  File \"/usr/local/lib/python3.10/site-packages/mage_ai/orchestration/queue/process_queue.py\", line 240, in run\n    start_session_and_run(args[1], *args[2], **args[3])\n", "  File \"/usr/local/lib/python3.10/site-packages/mage_ai/orchestration/db/process.py\", line 15, in start_session_and_run\n    results = target(*args)\n", "  File \"/usr/local/lib/python3.10/site-packages/mage_ai/orchestration/pipeline_scheduler_original.py\", line 1105, in run_block\n    return ExecutorFactory.get_block_executor(\n", "  File \"/usr/local/lib/python3.10/site-packages/mage_ai/data_preparation/executors/block_executor.py\", line 607, in execute\n    self.logger.exception(\n", "  File \"/usr/local/lib/python3.10/site-packages/mage_ai/data_preparation/logging/logger.py\", line 30, in exception\n    self.__send_message('exception', message, **kwargs)\n", "  File \"/usr/local/lib/python3.10/site-packages/mage_ai/data_preparation/logging/logger.py\", line 59, in __send_message\n    data['error_stack'] = traceback.format_stack(),\n"]], "error_stacktrace": ["No connection currently open. Open a new connection to access this property."]}
Traceback (most recent call last):
  File "/usr/local/lib/python3.10/site-packages/mage_ai/io/base.py", line 345, in conn
    return self._ctx
AttributeError: 'Postgres' object has no attribute '_ctx'

During handling of the above exception, another exception occurred:

Traceback (most recent call last):
  File "/usr/local/lib/python3.10/site-packages/mage_ai/data_preparation/executors/block_executor.py", line 605, in execute
    result = __execute_with_retry()
  File "/usr/local/lib/python3.10/site-packages/mage_ai/shared/retry.py", line 54, in retry_func
    raise e
  File "/usr/local/lib/python3.10/site-packages/mage_ai/shared/retry.py", line 38, in retry_func
    return func(*args, **kwargs)
  File "/usr/local/lib/python3.10/site-packages/mage_ai/data_preparation/executors/block_executor.py", line 578, in __execute_with_retry
    return self._execute(
  File "/usr/local/lib/python3.10/site-packages/mage_ai/data_preparation/executors/block_executor.py", line 1052, in _execute
    result = self.block.execute_sync(
  File "/usr/local/lib/python3.10/site-packages/mage_ai/data_preparation/models/block/__init__.py", line 1285, in execute_sync
    raise err
  File "/usr/local/lib/python3.10/site-packages/mage_ai/data_preparation/models/block/__init__.py", line 1194, in execute_sync
    output = self.execute_block(
  File "/usr/local/lib/python3.10/site-packages/mage_ai/data_preparation/models/block/__init__.py", line 1509, in execute_block
    outputs = self._execute_block(
  File "/usr/local/lib/python3.10/site-packages/mage_ai/data_preparation/models/block/__init__.py", line 1665, in _execute_block
    outputs = self.execute_block_function(
  File "/usr/local/lib/python3.10/site-packages/mage_ai/data_preparation/models/block/__init__.py", line 1704, in execute_block_function
    output = block_function_updated(*input_vars, **global_vars)
  File "<string>", line 25, in export_data_to_postgres
  File "/usr/local/lib/python3.10/site-packages/mage_ai/io/sql.py", line 359, in export
    __process()
  File "/usr/local/lib/python3.10/site-packages/mage_ai/io/sql.py", line 292, in __process
    table_exists = self.table_exists(schema_name, table_name)
  File "/usr/local/lib/python3.10/site-packages/mage_ai/io/postgres.py", line 166, in table_exists
    with self.conn.cursor() as cur:
  File "/usr/local/lib/python3.10/site-packages/mage_ai/io/base.py", line 347, in conn
    raise ConnectionError(
ConnectionError: No connection currently open. Open a new connection to access this property.
