2024-04-01T19:00:06 {"cpu": 0.0966796875, "cpu_total": 16, "cpu_usage": 0.00604248046875, "memory": 2799.0, "memory_total": 9698.0, "memory_usage": 0.2886162095277377, "pipeline_run_id": 299, "pipeline_schedule_id": 4, "pipeline_uuid": "fore_to_postgres", "hostname": "21e5326a3a0e", "level": "INFO", "message": "Pipeline fore_to_postgres for run 299 in schedule 4 is alive.", "timestamp": 1711998006.812098, "uuid": "390eeb7d2c5b45beb62ea004d2985763"}
2024-04-01T19:00:07 {"block_run_id": 805, "block_uuid": "scrape_full_fore", "pipeline_run_id": 299, "pipeline_schedule_id": 4, "pipeline_uuid": "fore_to_postgres", "hostname": "21e5326a3a0e", "level": "INFO", "message": "Execute PipelineRun 299, BlockRun 805: pipeline fore_to_postgres block scrape_full_fore", "timestamp": 1711998007.056918, "uuid": "a2ab6bb983b348be8d13d921eb7dca90"}
2024-04-01T19:00:08 {"cpu": 0.0966796875, "cpu_total": 16, "cpu_usage": 0.00604248046875, "memory": 2906.0, "memory_total": 9698.0, "memory_usage": 0.29964941224994845, "pipeline_run_id": 299, "pipeline_schedule_id": 4, "pipeline_uuid": "fore_to_postgres", "hostname": "21e5326a3a0e", "level": "INFO", "message": "Pipeline fore_to_postgres for run 299 in schedule 4 is alive.", "timestamp": 1711998008.257754, "uuid": "8270320992724d29b024d700842debc9"}
2024-04-01T19:00:17 {"cpu": 0.11669921875, "cpu_total": 16, "cpu_usage": 0.007293701171875, "memory": 2830.0, "memory_total": 9698.0, "memory_usage": 0.2918127448958548, "pipeline_run_id": 299, "pipeline_schedule_id": 4, "pipeline_uuid": "fore_to_postgres", "hostname": "21e5326a3a0e", "level": "INFO", "message": "Pipeline fore_to_postgres for run 299 in schedule 4 is alive.", "timestamp": 1711998017.160747, "uuid": "2d4d3a03f964490e80a414e61aebb914"}
2024-04-01T19:00:27 {"cpu": 0.13134765625, "cpu_total": 16, "cpu_usage": 0.008209228515625, "memory": 2962.0, "memory_total": 9698.0, "memory_usage": 0.30542379872138586, "pipeline_run_id": 299, "pipeline_schedule_id": 4, "pipeline_uuid": "fore_to_postgres", "hostname": "21e5326a3a0e", "level": "INFO", "message": "Pipeline fore_to_postgres for run 299 in schedule 4 is alive.", "timestamp": 1711998027.19987, "uuid": "19d7899d974f4ba386530b89991ff439"}
2024-04-01T19:00:38 {"cpu": 0.13427734375, "cpu_total": 16, "cpu_usage": 0.008392333984375, "memory": 2970.0, "memory_total": 9698.0, "memory_usage": 0.30624871107444834, "pipeline_run_id": 299, "pipeline_schedule_id": 4, "pipeline_uuid": "fore_to_postgres", "hostname": "21e5326a3a0e", "level": "INFO", "message": "Pipeline fore_to_postgres for run 299 in schedule 4 is alive.", "timestamp": 1711998038.836759, "uuid": "f1e4295f5e9b420b81d97aa17ad070c1"}
2024-04-01T19:00:48 {"cpu": 0.13330078125, "cpu_total": 16, "cpu_usage": 0.008331298828125, "memory": 2974.0, "memory_total": 9698.0, "memory_usage": 0.3066611672509796, "pipeline_run_id": 299, "pipeline_schedule_id": 4, "pipeline_uuid": "fore_to_postgres", "hostname": "21e5326a3a0e", "level": "INFO", "message": "Pipeline fore_to_postgres for run 299 in schedule 4 is alive.", "timestamp": 1711998048.448164, "uuid": "e6fbdb5e42334c4491c0ac6959d30868"}
2024-04-01T19:00:59 {"cpu": 0.13623046875, "cpu_total": 16, "cpu_usage": 0.008514404296875, "memory": 2975.0, "memory_total": 9698.0, "memory_usage": 0.3067642812951124, "pipeline_run_id": 299, "pipeline_schedule_id": 4, "pipeline_uuid": "fore_to_postgres", "hostname": "21e5326a3a0e", "level": "INFO", "message": "Pipeline fore_to_postgres for run 299 in schedule 4 is alive.", "timestamp": 1711998059.071711, "uuid": "b995fc8304c74f0e829643b7bbc0c0da"}
2024-04-01T19:01:03 {"block_run_id": 805, "block_uuid": "scrape_full_fore", "pipeline_run_id": 299, "pipeline_schedule_id": 4, "pipeline_uuid": "fore_to_postgres", "hostname": "21e5326a3a0e", "level": "EXCEPTION", "message": "BlockRun 805 (block_uuid: scrape_full_fore) failed.", "timestamp": 1711998063.88704, "uuid": "9de4be0ef4b04f84aa58e164b4e72695", "error": ["Traceback (most recent call last):\n  File \"/usr/local/lib/python3.10/urllib/request.py\", line 1348, in do_open\n    h.request(req.get_method(), req.selector, req.data, headers,\n  File \"/usr/local/lib/python3.10/http/client.py\", line 1283, in request\n    self._send_request(method, url, body, headers, encode_chunked)\n  File \"/usr/local/lib/python3.10/http/client.py\", line 1329, in _send_request\n    self.endheaders(body, encode_chunked=encode_chunked)\n  File \"/usr/local/lib/python3.10/http/client.py\", line 1278, in endheaders\n    self._send_output(message_body, encode_chunked=encode_chunked)\n  File \"/usr/local/lib/python3.10/http/client.py\", line 1038, in _send_output\n    self.send(msg)\n  File \"/usr/local/lib/python3.10/http/client.py\", line 976, in send\n    self.connect()\n  File \"/usr/local/lib/python3.10/http/client.py\", line 1455, in connect\n    self.sock = self._context.wrap_socket(self.sock,\n  File \"/usr/local/lib/python3.10/ssl.py\", line 513, in wrap_socket\n    return self.sslsocket_class._create(\n  File \"/usr/local/lib/python3.10/ssl.py\", line 1104, in _create\n    self.do_handshake()\n  File \"/usr/local/lib/python3.10/ssl.py\", line 1375, in do_handshake\n    self._sslobj.do_handshake()\nssl.SSLEOFError: [SSL: UNEXPECTED_EOF_WHILE_READING] EOF occurred in violation of protocol (_ssl.c:1007)\n\nDuring handling of the above exception, another exception occurred:\n\nTraceback (most recent call last):\n  File \"/usr/local/lib/python3.10/site-packages/mage_ai/data_preparation/executors/block_executor.py\", line 605, in execute\n    result = __execute_with_retry()\n  File \"/usr/local/lib/python3.10/site-packages/mage_ai/shared/retry.py\", line 54, in retry_func\n    raise e\n  File \"/usr/local/lib/python3.10/site-packages/mage_ai/shared/retry.py\", line 38, in retry_func\n    return func(*args, **kwargs)\n  File \"/usr/local/lib/python3.10/site-packages/mage_ai/data_preparation/executors/block_executor.py\", line 578, in __execute_with_retry\n    return self._execute(\n  File \"/usr/local/lib/python3.10/site-packages/mage_ai/data_preparation/executors/block_executor.py\", line 1052, in _execute\n    result = self.block.execute_sync(\n  File \"/usr/local/lib/python3.10/site-packages/mage_ai/data_preparation/models/block/__init__.py\", line 1285, in execute_sync\n    raise err\n  File \"/usr/local/lib/python3.10/site-packages/mage_ai/data_preparation/models/block/__init__.py\", line 1194, in execute_sync\n    output = self.execute_block(\n  File \"/usr/local/lib/python3.10/site-packages/mage_ai/data_preparation/models/block/__init__.py\", line 1509, in execute_block\n    outputs = self._execute_block(\n  File \"/usr/local/lib/python3.10/site-packages/mage_ai/data_preparation/models/block/__init__.py\", line 1665, in _execute_block\n    outputs = self.execute_block_function(\n  File \"/usr/local/lib/python3.10/site-packages/mage_ai/data_preparation/models/block/__init__.py\", line 1704, in execute_block_function\n    output = block_function_updated(*input_vars, **global_vars)\n  File \"<string>\", line 16, in load_data\n  File \"/home/src/./scrape_mountain_weather_data.py\", line 379, in scrape_weather\n    scrape_mtn_full_forecast_table_at_elev(mtn_name, elev))\n  File \"/home/src/./scrape_mountain_weather_data.py\", line 323, in scrape_mtn_full_forecast_table_at_elev\n    html = urlopen(url).read().decode(\"utf-8\")\n  File \"/usr/local/lib/python3.10/urllib/request.py\", line 216, in urlopen\n    return opener.open(url, data, timeout)\n  File \"/usr/local/lib/python3.10/urllib/request.py\", line 525, in open\n    response = meth(req, response)\n  File \"/usr/local/lib/python3.10/urllib/request.py\", line 634, in http_response\n    response = self.parent.error(\n  File \"/usr/local/lib/python3.10/urllib/request.py\", line 557, in error\n    result = self._call_chain(*args)\n  File \"/usr/local/lib/python3.10/urllib/request.py\", line 496, in _call_chain\n    result = func(*args)\n  File \"/usr/local/lib/python3.10/urllib/request.py\", line 749, in http_error_302\n    return self.parent.open(new, timeout=req.timeout)\n  File \"/usr/local/lib/python3.10/urllib/request.py\", line 519, in open\n    response = self._open(req, data)\n  File \"/usr/local/lib/python3.10/urllib/request.py\", line 536, in _open\n    result = self._call_chain(self.handle_open, protocol, protocol +\n  File \"/usr/local/lib/python3.10/urllib/request.py\", line 496, in _call_chain\n    result = func(*args)\n  File \"/usr/local/lib/python3.10/urllib/request.py\", line 1391, in https_open\n    return self.do_open(http.client.HTTPSConnection, req,\n  File \"/usr/local/lib/python3.10/urllib/request.py\", line 1351, in do_open\n    raise URLError(err)\nurllib.error.URLError: <urlopen error [SSL: UNEXPECTED_EOF_WHILE_READING] EOF occurred in violation of protocol (_ssl.c:1007)>\n"], "error_stack": [["  File \"/usr/local/bin/mage\", line 8, in <module>\n    sys.exit(app())\n", "  File \"/usr/local/lib/python3.10/site-packages/typer/main.py\", line 311, in __call__\n    return get_command(self)(*args, **kwargs)\n", "  File \"/usr/local/lib/python3.10/site-packages/click/core.py\", line 1130, in __call__\n    return self.main(*args, **kwargs)\n", "  File \"/usr/local/lib/python3.10/site-packages/typer/core.py\", line 778, in main\n    return _main(\n", "  File \"/usr/local/lib/python3.10/site-packages/typer/core.py\", line 216, in _main\n    rv = self.invoke(ctx)\n", "  File \"/usr/local/lib/python3.10/site-packages/click/core.py\", line 1657, in invoke\n    return _process_result(sub_ctx.command.invoke(sub_ctx))\n", "  File \"/usr/local/lib/python3.10/site-packages/click/core.py\", line 1404, in invoke\n    return ctx.invoke(self.callback, **ctx.params)\n", "  File \"/usr/local/lib/python3.10/site-packages/click/core.py\", line 760, in invoke\n    return __callback(*args, **kwargs)\n", "  File \"/usr/local/lib/python3.10/site-packages/typer/main.py\", line 683, in wrapper\n    return callback(**use_params)  # type: ignore\n", "  File \"/usr/local/lib/python3.10/site-packages/mage_ai/cli/main.py\", line 163, in start\n    start_server(\n", "  File \"/usr/local/lib/python3.10/site-packages/mage_ai/server/server.py\", line 659, in start_server\n    scheduler_manager.start_scheduler()\n", "  File \"/usr/local/lib/python3.10/site-packages/mage_ai/server/scheduler_manager.py\", line 87, in start_scheduler\n    proc.start()\n", "  File \"/usr/local/lib/python3.10/multiprocessing/process.py\", line 121, in start\n    self._popen = self._Popen(self)\n", "  File \"/usr/local/lib/python3.10/multiprocessing/context.py\", line 224, in _Popen\n    return _default_context.get_context().Process._Popen(process_obj)\n", "  File \"/usr/local/lib/python3.10/multiprocessing/context.py\", line 281, in _Popen\n    return Popen(process_obj)\n", "  File \"/usr/local/lib/python3.10/multiprocessing/popen_fork.py\", line 19, in __init__\n    self._launch(process_obj)\n", "  File \"/usr/local/lib/python3.10/multiprocessing/popen_fork.py\", line 71, in _launch\n    code = process_obj._bootstrap(parent_sentinel=child_r)\n", "  File \"/usr/local/lib/python3.10/multiprocessing/process.py\", line 314, in _bootstrap\n    self.run()\n", "  File \"/usr/local/lib/python3.10/multiprocessing/process.py\", line 108, in run\n    self._target(*self._args, **self._kwargs)\n", "  File \"/usr/local/lib/python3.10/site-packages/mage_ai/orchestration/db/process.py\", line 15, in start_session_and_run\n    results = target(*args)\n", "  File \"/usr/local/lib/python3.10/site-packages/mage_ai/server/scheduler_manager.py\", line 50, in run_scheduler\n    LoopTimeTrigger().start()\n", "  File \"/usr/local/lib/python3.10/site-packages/mage_ai/orchestration/triggers/loop_time_trigger.py\", line 14, in start\n    self.run()\n", "  File \"/usr/local/lib/python3.10/site-packages/mage_ai/orchestration/triggers/time_trigger.py\", line 11, in run\n    schedule_all()\n", "  File \"/usr/local/lib/python3.10/site-packages/mage_ai/orchestration/pipeline_scheduler_original.py\", line 1552, in schedule_all\n    PipelineScheduler(r).start()\n", "  File \"/usr/local/lib/python3.10/site-packages/mage_ai/orchestration/db/__init__.py\", line 149, in func_with_rollback\n    return func(*args, **kwargs)\n", "  File \"/usr/local/lib/python3.10/site-packages/mage_ai/orchestration/pipeline_scheduler_original.py\", line 182, in start\n    self.schedule()\n", "  File \"/usr/local/lib/python3.10/site-packages/mage_ai/orchestration/db/__init__.py\", line 149, in func_with_rollback\n    return func(*args, **kwargs)\n", "  File \"/usr/local/lib/python3.10/site-packages/mage_ai/orchestration/pipeline_scheduler_original.py\", line 319, in schedule\n    self.__schedule_blocks(block_runs)\n", "  File \"/usr/local/lib/python3.10/site-packages/mage_ai/orchestration/pipeline_scheduler_original.py\", line 581, in __schedule_blocks\n    job_manager.add_job(\n", "  File \"/usr/local/lib/python3.10/site-packages/mage_ai/orchestration/job_manager.py\", line 27, in add_job\n    self.queue.enqueue(job_id, target, *args, **kwargs)\n", "  File \"/usr/local/lib/python3.10/site-packages/mage_ai/orchestration/queue/process_queue.py\", line 107, in enqueue\n    self.start_worker_pool()\n", "  File \"/usr/local/lib/python3.10/site-packages/mage_ai/orchestration/queue/process_queue.py\", line 173, in start_worker_pool\n    self.worker_pool_proc.start()\n", "  File \"/usr/local/lib/python3.10/multiprocessing/process.py\", line 121, in start\n    self._popen = self._Popen(self)\n", "  File \"/usr/local/lib/python3.10/multiprocessing/context.py\", line 224, in _Popen\n    return _default_context.get_context().Process._Popen(process_obj)\n", "  File \"/usr/local/lib/python3.10/multiprocessing/context.py\", line 281, in _Popen\n    return Popen(process_obj)\n", "  File \"/usr/local/lib/python3.10/multiprocessing/popen_fork.py\", line 19, in __init__\n    self._launch(process_obj)\n", "  File \"/usr/local/lib/python3.10/multiprocessing/popen_fork.py\", line 71, in _launch\n    code = process_obj._bootstrap(parent_sentinel=child_r)\n", "  File \"/usr/local/lib/python3.10/multiprocessing/process.py\", line 314, in _bootstrap\n    self.run()\n", "  File \"/usr/local/lib/python3.10/multiprocessing/process.py\", line 108, in run\n    self._target(*self._args, **self._kwargs)\n", "  File \"/usr/local/lib/python3.10/site-packages/mage_ai/orchestration/queue/process_queue.py\", line 275, in poll_job_and_execute\n    worker.start()\n", "  File \"/usr/local/lib/python3.10/multiprocessing/process.py\", line 121, in start\n    self._popen = self._Popen(self)\n", "  File \"/usr/local/lib/python3.10/multiprocessing/context.py\", line 224, in _Popen\n    return _default_context.get_context().Process._Popen(process_obj)\n", "  File \"/usr/local/lib/python3.10/multiprocessing/context.py\", line 281, in _Popen\n    return Popen(process_obj)\n", "  File \"/usr/local/lib/python3.10/multiprocessing/popen_fork.py\", line 19, in __init__\n    self._launch(process_obj)\n", "  File \"/usr/local/lib/python3.10/multiprocessing/popen_fork.py\", line 71, in _launch\n    code = process_obj._bootstrap(parent_sentinel=child_r)\n", "  File \"/usr/local/lib/python3.10/multiprocessing/process.py\", line 314, in _bootstrap\n    self.run()\n", "  File \"/usr/local/lib/python3.10/site-packages/newrelic/api/background_task.py\", line 117, in wrapper\n    return wrapped(*args, **kwargs)\n", "  File \"/usr/local/lib/python3.10/site-packages/mage_ai/orchestration/queue/process_queue.py\", line 240, in run\n    start_session_and_run(args[1], *args[2], **args[3])\n", "  File \"/usr/local/lib/python3.10/site-packages/mage_ai/orchestration/db/process.py\", line 15, in start_session_and_run\n    results = target(*args)\n", "  File \"/usr/local/lib/python3.10/site-packages/mage_ai/orchestration/pipeline_scheduler_original.py\", line 1105, in run_block\n    return ExecutorFactory.get_block_executor(\n", "  File \"/usr/local/lib/python3.10/site-packages/mage_ai/data_preparation/executors/block_executor.py\", line 621, in execute\n    on_failure(\n", "  File \"/usr/local/lib/python3.10/site-packages/mage_ai/orchestration/db/__init__.py\", line 149, in func_with_rollback\n    return func(*args, **kwargs)\n", "  File \"/usr/local/lib/python3.10/site-packages/mage_ai/orchestration/pipeline_scheduler_original.py\", line 415, in on_block_failure\n    self.logger.exception(\n", "  File \"/usr/local/lib/python3.10/site-packages/mage_ai/data_preparation/logging/logger.py\", line 30, in exception\n    self.__send_message('exception', message, **kwargs)\n", "  File \"/usr/local/lib/python3.10/site-packages/mage_ai/data_preparation/logging/logger.py\", line 59, in __send_message\n    data['error_stack'] = traceback.format_stack(),\n"]], "error_stacktrace": ["<urlopen error [SSL: UNEXPECTED_EOF_WHILE_READING] EOF occurred in violation of protocol (_ssl.c:1007)>"]}
Traceback (most recent call last):
  File "/usr/local/lib/python3.10/urllib/request.py", line 1348, in do_open
    h.request(req.get_method(), req.selector, req.data, headers,
  File "/usr/local/lib/python3.10/http/client.py", line 1283, in request
    self._send_request(method, url, body, headers, encode_chunked)
  File "/usr/local/lib/python3.10/http/client.py", line 1329, in _send_request
    self.endheaders(body, encode_chunked=encode_chunked)
  File "/usr/local/lib/python3.10/http/client.py", line 1278, in endheaders
    self._send_output(message_body, encode_chunked=encode_chunked)
  File "/usr/local/lib/python3.10/http/client.py", line 1038, in _send_output
    self.send(msg)
  File "/usr/local/lib/python3.10/http/client.py", line 976, in send
    self.connect()
  File "/usr/local/lib/python3.10/http/client.py", line 1455, in connect
    self.sock = self._context.wrap_socket(self.sock,
  File "/usr/local/lib/python3.10/ssl.py", line 513, in wrap_socket
    return self.sslsocket_class._create(
  File "/usr/local/lib/python3.10/ssl.py", line 1104, in _create
    self.do_handshake()
  File "/usr/local/lib/python3.10/ssl.py", line 1375, in do_handshake
    self._sslobj.do_handshake()
ssl.SSLEOFError: [SSL: UNEXPECTED_EOF_WHILE_READING] EOF occurred in violation of protocol (_ssl.c:1007)

During handling of the above exception, another exception occurred:

Traceback (most recent call last):
  File "/usr/local/lib/python3.10/site-packages/mage_ai/data_preparation/executors/block_executor.py", line 605, in execute
    result = __execute_with_retry()
  File "/usr/local/lib/python3.10/site-packages/mage_ai/shared/retry.py", line 54, in retry_func
    raise e
  File "/usr/local/lib/python3.10/site-packages/mage_ai/shared/retry.py", line 38, in retry_func
    return func(*args, **kwargs)
  File "/usr/local/lib/python3.10/site-packages/mage_ai/data_preparation/executors/block_executor.py", line 578, in __execute_with_retry
    return self._execute(
  File "/usr/local/lib/python3.10/site-packages/mage_ai/data_preparation/executors/block_executor.py", line 1052, in _execute
    result = self.block.execute_sync(
  File "/usr/local/lib/python3.10/site-packages/mage_ai/data_preparation/models/block/__init__.py", line 1285, in execute_sync
    raise err
  File "/usr/local/lib/python3.10/site-packages/mage_ai/data_preparation/models/block/__init__.py", line 1194, in execute_sync
    output = self.execute_block(
  File "/usr/local/lib/python3.10/site-packages/mage_ai/data_preparation/models/block/__init__.py", line 1509, in execute_block
    outputs = self._execute_block(
  File "/usr/local/lib/python3.10/site-packages/mage_ai/data_preparation/models/block/__init__.py", line 1665, in _execute_block
    outputs = self.execute_block_function(
  File "/usr/local/lib/python3.10/site-packages/mage_ai/data_preparation/models/block/__init__.py", line 1704, in execute_block_function
    output = block_function_updated(*input_vars, **global_vars)
  File "<string>", line 16, in load_data
  File "/home/src/./scrape_mountain_weather_data.py", line 379, in scrape_weather
    scrape_mtn_full_forecast_table_at_elev(mtn_name, elev))
  File "/home/src/./scrape_mountain_weather_data.py", line 323, in scrape_mtn_full_forecast_table_at_elev
    html = urlopen(url).read().decode("utf-8")
  File "/usr/local/lib/python3.10/urllib/request.py", line 216, in urlopen
    return opener.open(url, data, timeout)
  File "/usr/local/lib/python3.10/urllib/request.py", line 525, in open
    response = meth(req, response)
  File "/usr/local/lib/python3.10/urllib/request.py", line 634, in http_response
    response = self.parent.error(
  File "/usr/local/lib/python3.10/urllib/request.py", line 557, in error
    result = self._call_chain(*args)
  File "/usr/local/lib/python3.10/urllib/request.py", line 496, in _call_chain
    result = func(*args)
  File "/usr/local/lib/python3.10/urllib/request.py", line 749, in http_error_302
    return self.parent.open(new, timeout=req.timeout)
  File "/usr/local/lib/python3.10/urllib/request.py", line 519, in open
    response = self._open(req, data)
  File "/usr/local/lib/python3.10/urllib/request.py", line 536, in _open
    result = self._call_chain(self.handle_open, protocol, protocol +
  File "/usr/local/lib/python3.10/urllib/request.py", line 496, in _call_chain
    result = func(*args)
  File "/usr/local/lib/python3.10/urllib/request.py", line 1391, in https_open
    return self.do_open(http.client.HTTPSConnection, req,
  File "/usr/local/lib/python3.10/urllib/request.py", line 1351, in do_open
    raise URLError(err)
urllib.error.URLError: <urlopen error [SSL: UNEXPECTED_EOF_WHILE_READING] EOF occurred in violation of protocol (_ssl.c:1007)>
2024-04-01T19:01:08 {"cpu": 0.13525390625, "cpu_total": 16, "cpu_usage": 0.008453369140625, "memory": 2953.0, "memory_total": 9698.0, "memory_usage": 0.30449577232419056, "pipeline_run_id": 299, "pipeline_schedule_id": 4, "pipeline_uuid": "fore_to_postgres", "hostname": "21e5326a3a0e", "level": "INFO", "message": "Pipeline fore_to_postgres for run 299 in schedule 4 is alive.", "timestamp": 1711998068.69655, "uuid": "29d1ccb88d0944b2bee4de8e10b3d8cd"}
